<mujoco model="2-link 6-muscle arm">
    <!--  Copyright © 2018, Roboti LLC

          This file is licensed under the MuJoCo Resource License (the "License").
          You may not use this file except in compliance with the License.
          You may obtain a copy of the License at

            https://www.roboti.us/resourcelicense.txt
    -->

    <option timestep="0.002" iterations="50" solver="Newton" tolerance="1e-10"/>

    <size njmax="500" nconmax="100" nstack="2000"/>

    <visual>
        <rgba haze=".3 .3 .3 1"/>
    </visual>

    <default>
        <muscle ctrllimited="true" ctrlrange="0 1"/>
        <joint armature="0.01" damping=".1" limited="true"/>
        <geom conaffinity="0" condim="3" contype="1" density="1000" friction=".7 .1 .1" rgba="0.8 0.6 .4 1"/>
    </default>

    <asset>
        <texture type="skybox" builtin="gradient" rgb1="0.6 0.6 0.6" rgb2="0 0 0" width="512" height="512"/> 

        <texture name="texplane" type="2d" builtin="checker" rgb1=".25 .25 .25" rgb2=".3 .3 .3" width="512" height="512" mark="cross" markrgb=".8 .8 .8"/>  

        <material name="matplane" reflectance="0.3" texture="texplane" texrepeat="1 1" texuniform="true"/>
    </asset>

    <worldbody>
        <geom name="floor" pos="0 0 0" size="0 0 1" type="plane" material="matplane" conaffinity="1" condim="3"/>

        <light directional="true" diffuse=".8 .8 .8" specular=".2 .2 .2" pos="0 0 5" dir="0 0 -1"/>


        <body name="torso" pos="0 0 1.35">
          <camera name="track" mode="trackcom" pos="0 -3 1" xyaxes="1 0 0 0 0 1"/>
          <!--
          <joint armature="0" axis="1 0 0" damping="0" limited="false" name="rootx" pos="0 0 0" stiffness="0" type="slide"/>
          <joint armature="0" axis="0 0 1" damping="0" limited="false" name="rootz" pos="0 0 0" ref="1.25" stiffness="0" type="slide"/>
          <joint armature="0" axis="0 1 0" damping="0" limited="false" name="rooty" pos="0 0 1.25" stiffness="0" type="hinge"/>
-->
          <geom friction="0.9" fromto="0 0 -0.25 0 0 0.25" name="torso_geom" size="0.05" type="capsule"/>
          <geom name="kansetsu0" type="cylinder" size=".08" fromto="0 -.05 -0.25 0 0.05 -0.25" rgba=".5 .1 .8 .5" mass="0"/>
          <site name="t1" pos="0.1 0 -0.2" size="0.02"/>
          <site name="t2" pos="-0.1 0 -0.2" size="0.02"/>
          <site name="x00" pos="-0.2 0 -0.5" size="0.02" rgba="0 .7 0 1" group="1"/>
          <body name="thigh" pos="0 0 -.25">
            <joint axis="0 -1 0" name="thigh_joint" pos="0 0 0" range="0 150" type="hinge"/>
            <geom friction="0.9" fromto="0 0 -.5 0 0 0" name="thigh_geom" size="0.05" type="capsule" rgba=".5 .1 .1 1"/>
            <geom name="kansetsu1" type="cylinder" size=".08" fromto="0 -.05 -0.5 0 0.05 -0.5" rgba=".5 .1 .8 .5" mass="0"/>
            <site name="x10" pos="0.2 0 -0.5" size="0.02" rgba="0 .7 0 1" group="1"/>
            <site name="t10" pos="0.1 0 -0.4" size="0.02" rgba="0 .7 0 1" group="1"/>
            <body name="leg" pos="0 0 -0.5">
              <joint axis="0 -1 0" name="leg_joint" pos="0 0 0" range="-150 0" type="hinge"/>
              <geom friction="0.9" fromto="0 0 -0.5 0 0 0" name="leg_geom" size="0.04" type="capsule"/>
              <site name="l1" pos="0.05 0 -0.1" size="0.02"/>
              <site name="l2" pos="-0.05 0 -0.1" size="0.02"/>
              <body name="foot" pos="0 0 -0.5">
                <joint axis="0 -1 0" name="foot_joint" pos="0 0 0" range="-45 45" type="hinge"/>
                <geom friction="0.9" fromto="-0.1 0 0 0.2 0 0" name="foot_geom" size="0.06" type="capsule" rgba=".5 .1 .1 1"/>
                <site name="f1" pos="0.1 0 0.1" size="0.02"/>
                <site name="f2" pos="-0.1 0 0.1" size="0.02"/>
              </body>
            </body>
          </body>
          <body name="left_thigh" pos="0 0 -.25">
            <joint axis="0 -1 0" name="left_thigh_joint" pos="0 0 0" range="0 150" type="hinge"/>
            <geom friction="0.9" fromto="0 0 -.5 0 0 0" name="left_thigh_geom" size="0.05" type="capsule" rgba=".5 .1 .1 1"/>
            <geom name="lkansetsu1" type="cylinder" size=".08" fromto="0 -.05 -0.5 0 0.05 -0.5" rgba=".5 .1 .8 .5" mass="0"/>
            <site name="lx10" pos="0.2 0 -0.5" size="0.02" rgba="0 .7 0 1" group="1"/>
            <site name="lt10" pos="0.1 0 -0.4" size="0.02" rgba="0 .7 0 1" group="1"/>
            <body name="left_leg" pos="0 0 -0.5">
              <joint axis="0 -1 0" name="left_leg_joint" pos="0 0 0" range="-150 0" type="hinge"/>
              <geom friction="0.9" fromto="0 0 -0.5 0 0 0" name="left_leg_geom" size="0.04" type="capsule"/>
              <site name="ll1" pos="0.05 0 -0.1" size="0.02"/>
              <site name="ll2" pos="-0.05 0 -0.1" size="0.02"/>
              <body name="left_foot" pos="0 0 -0.5">
                <joint axis="0 -1 0" name="left_foot_joint" pos="0 0 0" range="-45 45" type="hinge"/>
                <geom friction="0.9" fromto="-0.1 0 0 0.2 0 0" name="left_foot_geom" size="0.06" type="capsule" rgba=".5 .1 .1 1"/>
                <site name="lf1" pos="0.1 0 0.1" size="0.02"/>
                <site name="lf2" pos="-0.1 0 0.1" size="0.02"/>
              </body>
            </body>
          </body>
        </body>

    </worldbody>

    <tendon>
        <spatial name="ft" width="0.01">
            <site site="t1"/>
            <geom geom="kansetsu0"/>
            <site site="t10"/>
            <geom geom="kansetsu1" sidesite="x10"/>
            <site site="l1"/>
        </spatial>

        <spatial name="bt" width="0.01">
            <site site="t2"/>
            <geom geom="kansetsu0" sidesite="x00"/>
            <site site="l2"/>
        </spatial>

        <spatial name="fl" width="0.01">
            <site site="l1"/>
            <site site="f1"/>
        </spatial>

        <spatial name="bl" width="0.01">
            <site site="l2"/>
            <site site="f2"/>
        </spatial>

        <spatial name="lft" width="0.01">
            <site site="t1"/>
            <geom geom="kansetsu0"/>
            <site site="lt10"/>
            <geom geom="lkansetsu1" sidesite="lx10"/>
            <site site="ll1"/>
        </spatial>

        <spatial name="lbt" width="0.01">
            <site site="t2"/>
            <geom geom="kansetsu0"/>
            <site site="ll2"/>
        </spatial>

        <spatial name="lfl" width="0.01">
            <site site="ll1"/>
            <site site="lf1"/>
        </spatial>

        <spatial name="lbl" width="0.01">
            <site site="ll2"/>
            <site site="lf2"/>
        </spatial>

    </tendon>   

    <actuator>
        <muscle name="ft" tendon="ft"/>
        <muscle name="bt" tendon="bt"/>
        <muscle name="fl" tendon="fl"/>
        <muscle name="bl" tendon="bl"/>
        <muscle name="lft" tendon="lft"/>
        <muscle name="lbt" tendon="lbt"/>
        <muscle name="lfl" tendon="lfl"/>
        <muscle name="lbl" tendon="lbl"/>
    </actuator>
</mujoco>
